Workbook

Sheet Sheet1
B1: Usage | D1: Usage | F1: Emis | G1: 0.005 | H1: SOA | I1: 0.25
A2: 2016 | B2: 16300000 | C2: tons | D2: =B2*907.185/1000000000 -> 14.787116 | E2: Tg | F2: =D2*$G$1*1000 -> 73.935578 | G2: Gg | H2: =F2*$I$1 -> 18.483894 | I2: Gg
A3: 2017 | B3: =($B$7-$B$2)/5+B2 -> 16880000 | C3: tons | D3: =B3*907.185/1000000000 -> 15.313283 | E3: Tg | F3: =D3*$G$1*1000 -> 76.566414 | G3: Gg | H3: =F3*$I$1 -> 19.141603 | I3: Gg
A4: 2018 | B4: =($B$7-$B$2)/5+B3 -> 17460000 | C4: tons | D4: =B4*907.185/1000000000 -> 15.83945 | E4: Tg | F4: =D4*$G$1*1000 -> 79.197251 | G4: Gg | H4: =F4*$I$1 -> 19.799313 | I4: Gg
A5: 2019 | B5: =($B$7-$B$2)/5+B4 -> 18040000 | C5: tons | D5: =B5*907.185/1000000000 -> 16.365617 | E5: Tg | F5: =D5*$G$1*1000 -> 81.828087 | G5: Gg | H5: =F5*$I$1 -> 20.457022 | I5: Gg
A6: 2020 | B6: =($B$7-$B$2)/5+B5 -> 18620000 | C6: tons | D6: =B6*907.185/1000000000 -> 16.891785 | E6: Tg | F6: =D6*$G$1*1000 -> 84.458923 | G6: Gg | H6: =F6*$I$1 -> 21.114731 | I6: Gg
A7: 2021 | B7: 19200000 | C7: tons | D7: =B7*907.185/1000000000 -> 17.417952 | E7: Tg | F7: =D7*$G$1*1000 -> 87.08976 | G7: Gg | H7: =F7*$I$1 -> 21.77244 | I7: Gg
J8: =0.005*B6 -> 93100 | K8: =175350*0.4 -> 70140 | L8: =2254762*0.1 -> 225476.2
F9: =F6*1000000/907.185 -> 93100 | K9: =SUM(J8:L8) -> 388716.2
E11: barrels | F11: short ton | H11: barrels | I11: short ton
D12: Jan | E12: 400000 | F12: =E12/5.5 -> 72727.273 | G12: =F12/$F$24 -> 0.011869436 | H12: 6034000 | I12: =H12/5.5 -> 1097090.9 | J12: =I12/$I$24 -> 0.047449044
D13: Feb | E13: 700000 | F13: =E13/5.5 -> 127272.73 | G13: =F13/$F$24 -> 0.020771513 | H13: 5631000 | I13: =H13/5.5 -> 1023818.2 | J13: =I13/$I$24 -> 0.044280008
D14: Mar | E14: 2100000 | F14: =E14/5.5 -> 381818.18 | G14: =F14/$F$24 -> 0.06231454 | H14: 7186000 | I14: =H14/5.5 -> 1306545.5 | J14: =I14/$I$24 -> 0.056507927
D15: Apr | E15: 2500000 | F15: =E15/5.5 -> 454545.45 | G15: =F15/$F$24 -> 0.074183976 | H15: 9543000 | I15: =H15/5.5 -> 1735090.9 | J15: =I15/$I$24 -> 0.075042464
D16: May | E16: 4000000 | F16: =E16/5.5 -> 727272.73 | G16: =F16/$F$24 -> 0.11869436 | H16: 11454000 | I16: =H16/5.5 -> 2082545.5 | J16: =I16/$I$24 -> 0.090069829
D17: June | E17: 4250000 | F17: =E17/5.5 -> 772727.27 | G17: =F17/$F$24 -> 0.12611276 | H17: 12385000 | I17: =H17/5.5 -> 2251818.2 | J17: =I17/$I$24 -> 0.097390853
D18: July | E18: 5050000 | F18: =E18/5.5 -> 918181.82 | G18: =F18/$F$24 -> 0.14985163 | H18: 15812000 | I18: =H18/5.5 -> 2874909.1 | J18: =I18/$I$24 -> 0.12433946
D19: Aug | E19: 5100000 | F19: =E19/5.5 -> 927272.73 | G19: =F19/$F$24 -> 0.15133531 | H19: 15704000 | I19: =H19/5.5 -> 2855272.7 | J19: =I19/$I$24 -> 0.12349019
D20: Sept | E20: 4100000 | F20: =E20/5.5 -> 745454.55 | G20: =F20/$F$24 -> 0.12166172 | H20: 14406000 | I20: =H20/5.5 -> 2619272.7 | J20: =I20/$I$24 -> 0.11328322
D21: Oct | E21: 3000000 | F21: =E21/5.5 -> 545454.55 | G21: =F21/$F$24 -> 0.089020772 | H21: 13579000 | I21: =H21/5.5 -> 2468909.1 | J21: =I21/$I$24 -> 0.10678001
D22: Nov | E22: 1800000 | F22: =E22/5.5 -> 327272.73 | G22: =F22/$F$24 -> 0.053412463 | H22: 9290000 | I22: =H22/5.5 -> 1689090.9 | J22: =I22/$I$24 -> 0.073052969
D23: Dec | E23: 700000 | F23: =E23/5.5 -> 127272.73 | G23: =F23/$F$24 -> 0.020771513 | H23: 6144000 | I23: =H23/5.5 -> 1117090.9 | J23: =I23/$I$24 -> 0.048314041
F24: =SUM(F12:F23) -> 6127272.7 | I24: =SUM(I12:I23) -> 23121455

Sheet Input
A1: # 2018; All numbers reported in short tons and retreived from the 2018 Asphalt Usage Survey
A2: PADD | B2: Paving | G2: Non-Paving | J2: Total
B3: Asphalt Cement | C3: Modified Asphalt Cement | D3: Cutback Asphalt | E3: Emulsified Asphalt | F3: Total Paving | G3: All Roofing | H3: Misc. | I3: Total Non-Paving | L3: Emission Factors [%] | M3: HMA Cement | N3: WMA Cement | O3: Cutback Asphalt | P3: Emulsified Asphalt | Q3: All Roofing
A4: PADD 1 - East Coast | M4: 0.005025 | N4: 0.003165 | O4: 0.407985 | P4: 0.09876 | Q4: 0.017951117
A5: New England | B5: 777486 | C5: 4299 | E5: 2734 | F5: =SUM(B5:E5) -> 784519 | G5: 12270 | I5: =SUM(G5:H5) -> 12270 | J5: =SUM(F5,I5) -> 796789
A6: Central Atlantic | B6: 1980145 | C6: 195159 | D6: 658 | E6: 169750 | F6: =SUM(B6:E6) -> 2345712 | G6: 593736 | I6: =SUM(G6:H6) -> 593736 | J6: =SUM(F6,I6) -> 2939448 | N6: 43 | O6: g/kg
A7: Lower Atlantic | B7: 2452084 | C7: 418286 | D7: 1104 | E7: 212768 | F7: =SUM(B7:E7) -> 3084242 | G7: 426755 | H7: 748 | I7: =SUM(G7:H7) -> 427503 | J7: =SUM(F7,I7) -> 3511745 | N7: =N6*0.00220462/0.00110231 -> 86 | O7: lb/ton
A8: PADD 1 | B8: =SUM(B5:B7) -> 5209715 | C8: =SUM(C5:C7) -> 617744 | D8: =SUM(D5:D7) -> 1762 | E8: =SUM(E5:E7) -> 385252 | F8: =SUM(F5:F7) -> 6214473 | G8: =SUM(G5:G7) -> 1032761 | H8: =SUM(H5:H7) -> 748 | I8: =SUM(I5:I7) -> 1033509 | J8: =SUM(J5:J7) -> 7247982 | N8: =N7/2000 -> 0.043 | O8: %
A9: PADD 2 - Midwest | M9: HMA | N9: WMA | O9: Cutback | P9: Emulsified | Q9: Roofing
A10: Midwest East | B10: 3494678 | C10: 347114 | D10: 40149 | E10: 543803 | F10: =SUM(B10:E10) -> 4425744 | G10: 621583 | H10: 3954 | I10: =SUM(G10:H10) -> 625537 | J10: =SUM(F10,I10) -> 5051281 | L10: Application | M10: 8.04 | N10: 4.32 | O10: 813.96 | P10: 195.51 | Q10: 0.40190242 | R10: *5% of roofing applied hot
A11: Midwest North | B11: 962782 | C11: 354865 | D11: 19294 | E11: 211898 | F11: =SUM(B11:E11) -> 1548839 | G11: 151206 | I11: =SUM(G11:H11) -> 151206 | J11: =SUM(F11,I11) -> 1700045 | L11: In-use Low | M11: 2.01 | N11: 2.01 | O11: 2.01 | P11: 2.01 | Q11: 35.500332
A12: Midwest South | B12: 832278 | C12: 264622 | D12: 32962 | E12: 161758 | F12: =SUM(B12:E12) -> 1291620 | G12: 240973 | H12: 10094 | I12: =SUM(G12:H12) -> 251067 | J12: =SUM(F12,I12) -> 1542687 | L12: In-use High | M12: =M11*5 -> 10.05 | N12: =N11*5 -> 10.05 | O12: =O11*5 -> 10.05 | P12: =P11*5 -> 10.05 | Q12: 86
A13: PADD 2 | B13: =SUM(B10:B12) -> 5289738 | C13: =SUM(C10:C12) -> 966601 | D13: =SUM(D10:D12) -> 92405 | E13: =SUM(E10:E12) -> 917459 | F13: =SUM(F10:F12) -> 7266203 | G13: =SUM(G10:G12) -> 1013762 | H13: =SUM(H10:H12) -> 14048 | I13: =SUM(I10:I12) -> 1027810 | J13: =SUM(J10:J12) -> 8294013 | L13: Solar Low | M13: 4.0136108 | N13: 4.0136108 | O13: 4.0136108 | P13: 4.0136108 | Q13: 4.136
A14: PADD 3 - Gulf Coast | L14: Solar High | M14: 11.04 | N14: 11.04 | O14: 11.04 | P14: 11.04 | Q14: 84
A15: Gulf Coast East | B15: 653813 | C15: 222543 | D15: 2115 | E15: 157739 | F15: =SUM(B15:E15) -> 1036210 | G15: 457847 | I15: =SUM(G15:H15) -> 457847 | J15: =SUM(F15,I15) -> 1494057 | L15: Final (no solar) | M15: =SUM(M10,M11)/2000 -> 0.005025 | N15: =SUM(N10,N11)/2000 -> 0.003165 | O15: =SUM(O10,O11)/2000 -> 0.407985 | P15: =SUM(P10,P11)/2000 -> 0.09876 | Q15: =SUM(Q10,Q11)/2000 -> 0.017951117
A16: Gulf Coast West | B16: 973308 | C16: 345539 | D16: 28180 | E16: 213925 | F16: =SUM(B16:E16) -> 1560952 | G16: 330109 | H16: 13075 | I16: =SUM(G16:H16) -> 343184 | J16: =SUM(F16,I16) -> 1904136
A17: PADD 3 | B17: =SUM(B15:B16) -> 1627121 | C17: =SUM(C15:C16) -> 568082 | D17: =SUM(D15:D16) -> 30295 | E17: =SUM(E15:E16) -> 371664 | F17: =SUM(F15:F16) -> 2597162 | G17: =SUM(G15:G16) -> 787956 | H17: =SUM(H15:H16) -> 13075 | I17: =SUM(I15:I16) -> 801031 | J17: =SUM(J15:J16) -> 3398193 | M17: HMA | N17: WMA | O17: Cutback | P17: Emulsified | Q17: Roofing
A18: PADD 4 - Rocky Mountain | L18: Application | M18: =M10/0.00220462*0.00110231 -> 4.02 | N18: =N10/0.00220462*0.00110231 -> 2.16 | O18: =O10/0.00220462*0.00110231 -> 406.98 | P18: =P10/0.00220462*0.00110231 -> 97.755 | Q18: =Q10/0.00220462*0.00110231 -> 0.20095121 | R18: g/kg
A19: Rocky Mountain | B19: 261807 | C19: 259297 | D19: 3239 | E19: 212391 | F19: =SUM(B19:E19) -> 736734 | G19: 8387 | I19: =SUM(G19:H19) -> 8387 | J19: =SUM(F19,I19) -> 745121 | L19: In-use Low | M19: =M11/0.00220462*0.00110231 -> 1.005 | N19: =N11/0.00220462*0.00110231 -> 1.005 | O19: =O11/0.00220462*0.00110231 -> 1.005 | P19: =P11/0.00220462*0.00110231 -> 1.005 | Q19: =Q11/0.00220462*0.00110231 -> 17.750166
A20: PADD 4 | B20: =B19 -> 261807 | C20: =C19 -> 259297 | D20: =D19 -> 3239 | E20: =E19 -> 212391 | F20: =F19 -> 736734 | G20: =G19 -> 8387 | H20: =H19 -> 0 | I20: =I19 -> 8387 | J20: =J19 -> 745121 | L20: In-use High | M20: =M12/0.00220462*0.00110231 -> 5.025 | N20: =N12/0.00220462*0.00110231 -> 5.025 | O20: =O12/0.00220462*0.00110231 -> 5.025 | P20: =P12/0.00220462*0.00110231 -> 5.025 | Q20: =Q12/0.00220462*0.00110231 -> 43
A21: PADD 5 - West Coast | L21: Solar Low | M21: =M13/0.00220462*0.00110231 -> 2.0068054 | N21: =N13/0.00220462*0.00110231 -> 2.0068054 | O21: =O13/0.00220462*0.00110231 -> 2.0068054 | P21: =P13/0.00220462*0.00110231 -> 2.0068054 | Q21: =Q13/0.00220462*0.00110231 -> 2.068
A22: West Coast (CA) | B22: 1200734 | C22: 40579 | D22: 36631 | E22: 103133 | F22: =SUM(B22:E22) -> 1381077 | G22: 190161 | I22: =SUM(G22:H22) -> 190161 | J22: =SUM(F22,I22) -> 1571238 | L22: Solar High | M22: =M14/0.00220462*0.00110231 -> 5.52 | N22: =N14/0.00220462*0.00110231 -> 5.52 | O22: =O14/0.00220462*0.00110231 -> 5.52 | P22: =P14/0.00220462*0.00110231 -> 5.52 | Q22: =Q14/0.00220462*0.00110231 -> 42
A23: West Coast (less CA) | B23: 756977 | C23: 192192 | D23: 4426 | E23: 170929 | F23: =SUM(B23:E23) -> 1124524 | G23: 174741 | I23: =SUM(G23:H23) -> 174741 | J23: =SUM(F23,I23) -> 1299265 | L23: Final (no solar) | M23: =SUM(M18:M19) -> 5.025 | N23: =SUM(N18:N19) -> 3.165 | O23: =SUM(O18:O19) -> 407.985 | P23: =SUM(P18:P19) -> 98.76 | Q23: =SUM(Q18:Q19) -> 17.951117
A24: PADD 5 | B24: =SUM(B22:B23) -> 1957711 | C24: =SUM(C22:C23) -> 232771 | D24: =SUM(D22:D23) -> 41057 | E24: =SUM(E22:E23) -> 274062 | F24: =SUM(F22:F23) -> 2505601 | G24: =SUM(G22:G23) -> 364902 | H24: =SUM(H22:H23) -> 0 | I24: =SUM(I22:I23) -> 364902 | J24: =SUM(J22:J23) -> 2870503
A25: Total U.S. | B25: =SUM(B8,B13,B17,B20,B24) -> 14346092 | C25: =SUM(C8,C13,C17,C20,C24) -> 2644495 | D25: =SUM(D8,D13,D17,D20,D24) -> 168758 | E25: =SUM(E8,E13,E17,E20,E24) -> 2160828 | F25: =SUM(F8,F13,F17,F20,F24) -> 19320173 | G25: =SUM(G8,G13,G17,G20,G24) -> 3207768 | H25: =SUM(H8,H13,H17,H20,H24) -> 27871 | I25: =SUM(I8,I13,I17,I20,I24) -> 3235639 | J25: =SUM(J8,J13,J17,J20,J24) -> 22555812
A27: # 2018; All numbers reported in thousand barrels; https://www.eia.gov/dnav/pet/pet_cons_psup_a_eppa_vpp_mbbl_m.htm
A28: Date | B28: U.S. | C28: PADD 1 | D28: PADD 2 | E28: PADD 3 | F28: PADD 4 | G28: PADD 5
A29: 43101 | B29: 4895 | C29: 35 | D29: 2590 | E29: 1205 | F29: 436 | G29: 629 | I29: Only used for seasonal cycle; can be used for activity in future
A30: 43132 | B30: 5691 | C30: 1295 | D30: 2119 | E30: 879 | F30: 493 | G30: 905
A31: 43133 | B31: 8625 | C31: 2994 | D31: 2805 | E31: 1346 | F31: 460 | G31: 1020
A32: 43134 | B32: 6747 | C32: 604 | D32: 2646 | E32: 1457 | F32: 377 | G32: 1663
A33: 43135 | B33: 11939 | C33: 3645 | D33: 4178 | E33: 1605 | F33: 584 | G33: 1926
A34: 43136 | B34: 14291 | C34: 4294 | D34: 5258 | E34: 2040 | F34: 996 | G34: 1703
A35: 43137 | B35: 14245 | C35: 4132 | D35: 5835 | E35: 1256 | F35: 997 | G35: 2025
A36: 43138 | B36: 15706 | C36: 4256 | D36: 5969 | E36: 2221 | F36: 1206 | G36: 2053
A37: 43139 | B37: 11555 | C37: 3989 | D37: 4258 | E37: 970 | F37: 942 | G37: 1395
A38: 43140 | B38: 12716 | C38: 4870 | D38: 5019 | E38: 821 | F38: 528 | G38: 1478
A39: 43141 | B39: 7423 | C39: 2223 | D39: 3217 | E39: 562 | F39: 332 | G39: 1089
A40: 43435 | B40: 5630 | C40: 1659 | D40: 2311 | E40: 220 | F40: 471 | G40: 969
A42: # 2018; All numbers reported in short tons; 5.5 short tons per barrel; https://www.eia.gov/dnav/pet/pet_cons_psup_a_eppa_vpp_mbbl_m.htm
...

Sheet Intermediate
A1: State | B1: PADD | C1: PADD Region | D1: HMA/WMA Produced (NAPA) | E1: WMA @ Reduced Temps (NAPA) | F1: Construction Expenditures (in Millions) | G1: Asphalt Cement | H1: HMA Cement | I1: WMA Cement | J1: Cutback Asphalt | K1: Emulsified Asphalt | L1: All Roofing | N1: PADD Region | O1: HMA/WMA Produced (NAPA) | P1: Construction Expenditures (in Millions)
A2: Alabama | B2: PADD 3 | C2: Gulf Coast East | D2: =VLOOKUP(A2,Input!$A$60:$B$110,2,FALSE) -> 6.7 | E2: =VLOOKUP(A2,Input!$A$60:$C$110,3,FALSE) -> 1.5 | F2: =Input!E60 -> 7525 | G2: =(VLOOKUP(C2,Input!$A$5:$I$24,2,FALSE)+VLOOKUP(C2,Input!$A$5:$I$24,3,FALSE))*(D2/VLOOKUP(C2,$N$2:$O$12,2,FALSE)) -> 234863.41 | H2: =G2-I2 -> 182282.05 | I2: =G2*(E2/D2) -> 52581.36 | J2: =VLOOKUP(C2,Input!$A$5:$I$24,4,FALSE)*(D2/VLOOKUP(C2,$N$2:$O$12,2,FALSE)) -> 566.82 | K2: =VLOOKUP(C2,Input!$A$5:$I$24,5,FALSE)*(D2/VLOOKUP(C2,$N$2:$O$12,2,FALSE)) -> 42274.052 | L2: =VLOOKUP(C2,Input!$A$5:$I$24,7,FALSE)*(F2/VLOOKUP(C2,$N$2:$P$12,3,FALSE)) -> 101757.3 | N2: Gulf Coast East | O2: =SUMIF($C$2:$C$52,"="&N2,$D$2:$D$52) -> 25 | P2: =SUMIF($C$2:$C$52,"="&N2,$F$2:$F$52) -> 33858
A3: Alaska | B3: PADD 5 | C3: West Coast (less CA) | D3: =VLOOKUP(A3,Input!$A$60:$B$110,2,FALSE) -> 2 | E3: =VLOOKUP(A3,Input!$A$60:$C$110,3,FALSE) -> 0 | F3: =Input!E61 -> 1704 | G3: =(VLOOKUP(C3,Input!$A$5:$I$24,2,FALSE)+VLOOKUP(C3,Input!$A$5:$I$24,3,FALSE))*(D3/VLOOKUP(C3,$N$2:$O$12,2,FALSE)) -> 74737.717 | H3: =G3-I3 -> 74737.717 | I3: =G3*(E3/D3) -> 0 | J3: =VLOOKUP(C3,Input!$A$5:$I$24,4,FALSE)*(D3/VLOOKUP(C3,$N$2:$O$12,2,FALSE)) -> 348.50394 | K3: =VLOOKUP(C3,Input!$A$5:$I$24,5,FALSE)*(D3/VLOOKUP(C3,$N$2:$O$12,2,FALSE)) -> 13458.976 | L3: =VLOOKUP(C3,Input!$A$5:$I$24,7,FALSE)*(F3/VLOOKUP(C3,$N$2:$P$12,3,FALSE)) -> 5825.2698 | N3: West Coast (CA) | O3: =SUMIF($C$2:$C$52,"="&N3,$D$2:$D$52) -> 27.7 | P3: =SUMIF($C$2:$C$52,"="&N3,$F$2:$F$52) -> 67703
A4: Arizona | B4: PADD 5 | C4: West Coast (less CA) | D4: =VLOOKUP(A4,Input!$A$60:$B$110,2,FALSE) -> 7.6 | E4: =VLOOKUP(A4,Input!$A$60:$C$110,3,FALSE) -> 0.3 | F4: =Input!E62 -> 9854 | G4: =(VLOOKUP(C4,Input!$A$5:$I$24,2,FALSE)+VLOOKUP(C4,Input!$A$5:$I$24,3,FALSE))*(D4/VLOOKUP(C4,$N$2:$O$12,2,FALSE)) -> 284003.32 | H4: =G4-I4 -> 272792.67 | I4: =G4*(E4/D4) -> 11210.657 | J4: =VLOOKUP(C4,Input!$A$5:$I$24,4,FALSE)*(D4/VLOOKUP(C4,$N$2:$O$12,2,FALSE)) -> 1324.315 | K4: =VLOOKUP(C4,Input!$A$5:$I$24,5,FALSE)*(D4/VLOOKUP(C4,$N$2:$O$12,2,FALSE)) -> 51144.11 | L4: =VLOOKUP(C4,Input!$A$5:$I$24,7,FALSE)*(F4/VLOOKUP(C4,$N$2:$P$12,3,FALSE)) -> 33686.742 | N4: West Coast (less CA) | O4: =SUMIF($C$2:$C$52,"="&N4,$D$2:$D$52) -> 25.4 | P4: =SUMIF($C$2:$C$52,"="&N4,$F$2:$F$52) -> 51115
A5: Arkansas | B5: PADD 3 | C5: Gulf Coast East | D5: =VLOOKUP(A5,Input!$A$60:$B$110,2,FALSE) -> 5.4 | E5: =VLOOKUP(A5,Input!$A$60:$C$110,3,FALSE) -> 0.4 | F5: =Input!E63 -> 5748 | G5: =(VLOOKUP(C5,Input!$A$5:$I$24,2,FALSE)+VLOOKUP(C5,Input!$A$5:$I$24,3,FALSE))*(D5/VLOOKUP(C5,$N$2:$O$12,2,FALSE)) -> 189292.9 | H5: =G5-I5 -> 175271.2 | I5: =G5*(E5/D5) -> 14021.696 | J5: =VLOOKUP(C5,Input!$A$5:$I$24,4,FALSE)*(D5/VLOOKUP(C5,$N$2:$O$12,2,FALSE)) -> 456.84 | K5: =VLOOKUP(C5,Input!$A$5:$I$24,5,FALSE)*(D5/VLOOKUP(C5,$N$2:$O$12,2,FALSE)) -> 34071.624 | L5: =VLOOKUP(C5,Input!$A$5:$I$24,7,FALSE)*(F5/VLOOKUP(C5,$N$2:$P$12,3,FALSE)) -> 77727.703 | N5: Rocky Mountain | O5: =SUMIF($C$2:$C$52,"="&N5,$D$2:$D$52) -> 21.4 | P5: =SUMIF($C$2:$C$52,"="&N5,$F$2:$F$52) -> 25660
A6: California | B6: PADD 5 | C6: West Coast (CA) | D6: =VLOOKUP(A6,Input!$A$60:$B$110,2,FALSE) -> 27.7 | E6: =VLOOKUP(A6,Input!$A$60:$C$110,3,FALSE) -> 4.5 | F6: =Input!E64 -> 67703 | G6: =(VLOOKUP(C6,Input!$A$5:$I$24,2,FALSE)+VLOOKUP(C6,Input!$A$5:$I$24,3,FALSE))*(D6/VLOOKUP(C6,$N$2:$O$12,2,FALSE)) -> 1241313 | H6: =G6-I6 -> 1039655.7 | I6: =G6*(E6/D6) -> 201657.35 | J6: =VLOOKUP(C6,Input!$A$5:$I$24,4,FALSE)*(D6/VLOOKUP(C6,$N$2:$O$12,2,FALSE)) -> 36631 | K6: =VLOOKUP(C6,Input!$A$5:$I$24,5,FALSE)*(D6/VLOOKUP(C6,$N$2:$O$12,2,FALSE)) -> 103133 | L6: =VLOOKUP(C6,Input!$A$5:$I$24,7,FALSE)*(F6/VLOOKUP(C6,$N$2:$P$12,3,FALSE)) -> 190161 | N6: New England | O6: =SUMIF($C$2:$C$52,"="&N6,$D$2:$D$52) -> 18.8 | P6: =SUMIF($C$2:$C$52,"="&N6,$F$2:$F$52) -> 28605
A7: Colorado | B7: PADD 4 | C7: Rocky Mountain | D7: =VLOOKUP(A7,Input!$A$60:$B$110,2,FALSE) -> 7.8 | E7: =VLOOKUP(A7,Input!$A$60:$C$110,3,FALSE) -> 1 | F7: =Input!E65 -> 13362 | G7: =(VLOOKUP(C7,Input!$A$5:$I$24,2,FALSE)+VLOOKUP(C7,Input!$A$5:$I$24,3,FALSE))*(D7/VLOOKUP(C7,$N$2:$O$12,2,FALSE)) -> 189935.1 | H7: =G7-I7 -> 165584.45 | I7: =G7*(E7/D7) -> 24350.654 | J7: =VLOOKUP(C7,Input!$A$5:$I$24,4,FALSE)*(D7/VLOOKUP(C7,$N$2:$O$12,2,FALSE)) -> 1180.5701 | K7: =VLOOKUP(C7,Input!$A$5:$I$24,5,FALSE)*(D7/VLOOKUP(C7,$N$2:$O$12,2,FALSE)) -> 77413.542 | L7: =VLOOKUP(C7,Input!$A$5:$I$24,7,FALSE)*(F7/VLOOKUP(C7,$N$2:$P$12,3,FALSE)) -> 4367.3848 | N7: Central Atlantic | O7: =SUMIF($C$2:$C$52,"="&N7,$D$2:$D$52) -> 57.1 | P7: =SUMIF($C$2:$C$52,"="&N7,$F$2:$F$52) -> 102041
A8: Connecticut | B8: PADD 1 | C8: New England | D8: =VLOOKUP(A8,Input!$A$60:$B$110,2,FALSE) -> 4.9 | E8: =VLOOKUP(A8,Input!$A$60:$C$110,3,FALSE) -> 0 | F8: =Input!E66 -> 5020 | G8: =(VLOOKUP(C8,Input!$A$5:$I$24,2,FALSE)+VLOOKUP(C8,Input!$A$5:$I$24,3,FALSE))*(D8/VLOOKUP(C8,$N$2:$O$12,2,FALSE)) -> 203763.11 | H8: =G8-I8 -> 203763.11 | I8: =G8*(E8/D8) -> 0 | J8: =VLOOKUP(C8,Input!$A$5:$I$24,4,FALSE)*(D8/VLOOKUP(C8,$N$2:$O$12,2,FALSE)) -> 0 | K8: =VLOOKUP(C8,Input!$A$5:$I$24,5,FALSE)*(D8/VLOOKUP(C8,$N$2:$O$12,2,FALSE)) -> 712.58511 | L8: =VLOOKUP(C8,Input!$A$5:$I$24,7,FALSE)*(F8/VLOOKUP(C8,$N$2:$P$12,3,FALSE)) -> 2153.3089 | N8: Lower Atlantic | O8: =SUMIF($C$2:$C$52,"="&N8,$D$2:$D$52) -> 72.2 | P8: =SUMIF($C$2:$C$52,"="&N8,$F$2:$F$52) -> 96805
A9: Delaware | B9: PADD 1 | C9: Central Atlantic | D9: =VLOOKUP(A9,Input!$A$60:$B$110,2,FALSE) -> 1.6 | E9: =VLOOKUP(A9,Input!$A$60:$C$110,3,FALSE) -> 0 | F9: =Input!E67 -> 2273 | G9: =(VLOOKUP(C9,Input!$A$5:$I$24,2,FALSE)+VLOOKUP(C9,Input!$A$5:$I$24,3,FALSE))*(D9/VLOOKUP(C9,$N$2:$O$12,2,FALSE)) -> 60954.228 | H9: =G9-I9 -> 60954.228 | I9: =G9*(E9/D9) -> 0 | J9: =VLOOKUP(C9,Input!$A$5:$I$24,4,FALSE)*(D9/VLOOKUP(C9,$N$2:$O$12,2,FALSE)) -> 18.437828 | K9: =VLOOKUP(C9,Input!$A$5:$I$24,5,FALSE)*(D9/VLOOKUP(C9,$N$2:$O$12,2,FALSE)) -> 4756.5674 | L9: =VLOOKUP(C9,Input!$A$5:$I$24,7,FALSE)*(F9/VLOOKUP(C9,$N$2:$P$12,3,FALSE)) -> 13225.683 | N9: Midwest East | O9: =SUMIF($C$2:$C$52,"="&N9,$D$2:$D$52) -> 70.9 | P9: =SUMIF($C$2:$C$52,"="&N9,$F$2:$F$52) -> 79462
A10: District of Columbia | B10: PADD 1 | C10: Central Atlantic | D10: =VLOOKUP(A10,Input!$A$60:$B$110,2,FALSE) -> 1.5 | E10: =VLOOKUP(A10,Input!$A$60:$C$110,3,FALSE) -> 0 | F10: =Input!E68 -> 4428 | G10: =(VLOOKUP(C10,Input!$A$5:$I$24,2,FALSE)+VLOOKUP(C10,Input!$A$5:$I$24,3,FALSE))*(D10/VLOOKUP(C10,$N$2:$O$12,2,FALSE)) -> 57144.588 | H10: =G10-I10 -> 57144.588 | I10: =G10*(E10/D10) -> 0 | J10: =VLOOKUP(C10,Input!$A$5:$I$24,4,FALSE)*(D10/VLOOKUP(C10,$N$2:$O$12,2,FALSE)) -> 17.285464 | K10: =VLOOKUP(C10,Input!$A$5:$I$24,5,FALSE)*(D10/VLOOKUP(C10,$N$2:$O$12,2,FALSE)) -> 4459.282 | L10: =VLOOKUP(C10,Input!$A$5:$I$24,7,FALSE)*(F10/VLOOKUP(C10,$N$2:$P$12,3,FALSE)) -> 25764.771 | N10: Midwest South | O10: =SUMIF($C$2:$C$52,"="&N10,$D$2:$D$52) -> 20.5 | P10: =SUMIF($C$2:$C$52,"="&N10,$F$2:$F$52) -> 35118
A11: Florida | B11: PADD 1 | C11: Lower Atlantic | D11: =VLOOKUP(A11,Input!$A$60:$B$110,2,FALSE) -> 16 | E11: =VLOOKUP(A11,Input!$A$60:$C$110,3,FALSE) -> 2.1 | F11: =Input!E69 -> 33689 | G11: =(VLOOKUP(C11,Input!$A$5:$I$24,2,FALSE)+VLOOKUP(C11,Input!$A$5:$I$24,3,FALSE))*(D11/VLOOKUP(C11,$N$2:$O$12,2,FALSE)) -> 636093.07 | H11: =G11-I11 -> 552605.86 | I11: =G11*(E11/D11) -> 83487.216 | J11: =VLOOKUP(C11,Input!$A$5:$I$24,4,FALSE)*(D11/VLOOKUP(C11,$N$2:$O$12,2,FALSE)) -> 244.65374 | K11: =VLOOKUP(C11,Input!$A$5:$I$24,5,FALSE)*(D11/VLOOKUP(C11,$N$2:$O$12,2,FALSE)) -> 47150.803 | L11: =VLOOKUP(C11,Input!$A$5:$I$24,7,FALSE)*(F11/VLOOKUP(C11,$N$2:$P$12,3,FALSE)) -> 148514.53 | N11: Midwest North | O11: =SUMIF($C$2:$C$52,"="&N11,$D$2:$D$52) -> 27.5 | P11: =SUMIF($C$2:$C$52,"="&N11,$F$2:$F$52) -> 28065
A12: Georgia | B12: PADD 1 | C12: Lower Atlantic | D12: =VLOOKUP(A12,Input!$A$60:$B$110,2,FALSE) -> 14.2 | E12: =VLOOKUP(A12,Input!$A$60:$C$110,3,FALSE) -> 0 | F12: =Input!E70 -> 17358 | G12: =(VLOOKUP(C12,Input!$A$5:$I$24,2,FALSE)+VLOOKUP(C12,Input!$A$5:$I$24,3,FALSE))*(D12/VLOOKUP(C12,$N$2:$O$12,2,FALSE)) -> 564532.6 | H12: =G12-I12 -> 564532.6 | I12: =G12*(E12/D12) -> 0 | J12: =VLOOKUP(C12,Input!$A$5:$I$24,4,FALSE)*(D12/VLOOKUP(C12,$N$2:$O$12,2,FALSE)) -> 217.13019 | K12: =VLOOKUP(C12,Input!$A$5:$I$24,5,FALSE)*(D12/VLOOKUP(C12,$N$2:$O$12,2,FALSE)) -> 41846.338 | L12: =VLOOKUP(C12,Input!$A$5:$I$24,7,FALSE)*(F12/VLOOKUP(C12,$N$2:$P$12,3,FALSE)) -> 76520.978 | N12: Gulf Coast West | O12: =SUMIF($C$2:$C$52,"="&N12,$D$2:$D$52) -> 21 | P12: =SUMIF($C$2:$C$52,"="&N12,$F$2:$F$52) -> 78671
A13: Hawaii | B13: PADD 5 | C13: West Coast (less CA) | D13: =VLOOKUP(A13,Input!$A$60:$B$110,2,FALSE) -> 1.1 | E13: =VLOOKUP(A13,Input!$A$60:$C$110,3,FALSE) -> 0 | F13: =Input!E71 -> 4426 | G13: =(VLOOKUP(C13,Input!$A$5:$I$24,2,FALSE)+VLOOKUP(C13,Input!$A$5:$I$24,3,FALSE))*(D13/VLOOKUP(C13,$N$2:$O$12,2,FALSE)) -> 41105.744 | H13: =G13-I13 -> 41105.744 | I13: =G13*(E13/D13) -> 0 | J13: =VLOOKUP(C13,Input!$A$5:$I$24,4,FALSE)*(D13/VLOOKUP(C13,$N$2:$O$12,2,FALSE)) -> 191.67717 | K13: =VLOOKUP(C13,Input!$A$5:$I$24,5,FALSE)*(D13/VLOOKUP(C13,$N$2:$O$12,2,FALSE)) -> 7402.437 | L13: =VLOOKUP(C13,Input!$A$5:$I$24,7,FALSE)*(F13/VLOOKUP(C13,$N$2:$P$12,3,FALSE)) -> 15130.66
A14: Idaho | B14: PADD 4 | C14: Rocky Mountain | D14: =VLOOKUP(A14,Input!$A$60:$B$110,2,FALSE) -> 2.9 | E14: =VLOOKUP(A14,Input!$A$60:$C$110,3,FALSE) -> 1.5 | F14: =Input!E72 -> 2871 | G14: =(VLOOKUP(C14,Input!$A$5:$I$24,2,FALSE)+VLOOKUP(C14,Input!$A$5:$I$24,3,FALSE))*(D14/VLOOKUP(C14,$N$2:$O$12,2,FALSE)) -> 70616.897 | H14: =G14-I14 -> 34090.916 | I14: =G14*(E14/D14) -> 36525.981 | J14: =VLOOKUP(C14,Input!$A$5:$I$24,4,FALSE)*(D14/VLOOKUP(C14,$N$2:$O$12,2,FALSE)) -> 438.92991 | K14: =VLOOKUP(C14,Input!$A$5:$I$24,5,FALSE)*(D14/VLOOKUP(C14,$N$2:$O$12,2,FALSE)) -> 28781.958 | L14: =VLOOKUP(C14,Input!$A$5:$I$24,7,FALSE)*(F14/VLOOKUP(C14,$N$2:$P$12,3,FALSE)) -> 938.38959
A15: Illinois | B15: PADD 2 | C15: Midwest East | D15: =VLOOKUP(A15,Input!$A$60:$B$110,2,FALSE) -> 12.5 | E15: =VLOOKUP(A15,Input!$A$60:$C$110,3,FALSE) -> 4.6 | F15: =Input!E73 -> 18084 | G15: =(VLOOKUP(C15,Input!$A$5:$I$24,2,FALSE)+VLOOKUP(C15,Input!$A$5:$I$24,3,FALSE))*(D15/VLOOKUP(C15,$N$2:$O$12,2,FALSE)) -> 677325.81 | H15: =G15-I15 -> 428069.91 | I15: =G15*(E15/D15) -> 249255.9 | J15: =VLOOKUP(C15,Input!$A$5:$I$24,4,FALSE)*(D15/VLOOKUP(C15,$N$2:$O$12,2,FALSE)) -> 7078.4556 | K15: =VLOOKUP(C15,Input!$A$5:$I$24,5,FALSE)*(D15/VLOOKUP(C15,$N$2:$O$12,2,FALSE)) -> 95875 | L15: =VLOOKUP(C15,Input!$A$5:$I$24,7,FALSE)*(F15/VLOOKUP(C15,$N$2:$P$12,3,FALSE)) -> 141460.16
A16: Indiana | B16: PADD 2 | C16: Midwest East | D16: =VLOOKUP(A16,Input!$A$60:$B$110,2,FALSE) -> 12.5 | E16: =VLOOKUP(A16,Input!$A$60:$C$110,3,FALSE) -> 3.7 | F16: =Input!E74 -> 10755 | G16: =(VLOOKUP(C16,Input!$A$5:$I$24,2,FALSE)+VLOOKUP(C16,Input!$A$5:$I$24,3,FALSE))*(D16/VLOOKUP(C16,$N$2:$O$12,2,FALSE)) -> 677325.81 | H16: =G16-I16 -> 476837.37 | I16: =G16*(E16/D16) -> 200488.44 | J16: =VLOOKUP(C16,Input!$A$5:$I$24,4,FALSE)*(D16/VLOOKUP(C16,$N$2:$O$12,2,FALSE)) -> 7078.4556 | K16: =VLOOKUP(C16,Input!$A$5:$I$24,5,FALSE)*(D16/VLOOKUP(C16,$N$2:$O$12,2,FALSE)) -> 95875 | L16: =VLOOKUP(C16,Input!$A$5:$I$24,7,FALSE)*(F16/VLOOKUP(C16,$N$2:$P$12,3,FALSE)) -> 84129.838
A17: Iowa | B17: PADD 2 | C17: Midwest South | D17: =VLOOKUP(A17,Input!$A$60:$B$110,2,FALSE) -> 3.8 | E17: =VLOOKUP(A17,Input!$A$60:$C$110,3,FALSE) -> 1.1 | F17: =Input!E75 -> 8357 | G17: =(VLOOKUP(C17,Input!$A$5:$I$24,2,FALSE)+VLOOKUP(C17,Input!$A$5:$I$24,3,FALSE))*(D17/VLOOKUP(C17,$N$2:$O$12,2,FALSE)) -> 203327.8 | H17: =G17-I17 -> 144469.76 | I17: =G17*(E17/D17) -> 58858.049 | J17: =VLOOKUP(C17,Input!$A$5:$I$24,4,FALSE)*(D17/VLOOKUP(C17,$N$2:$O$12,2,FALSE)) -> 6110.0293 | K17: =VLOOKUP(C17,Input!$A$5:$I$24,5,FALSE)*(D17/VLOOKUP(C17,$N$2:$O$12,2,FALSE)) -> 29984.41 | L17: =VLOOKUP(C17,Input!$A$5:$I$24,7,FALSE)*(F17/VLOOKUP(C17,$N$2:$P$12,3,FALSE)) -> 57344.136
A18: Kansas | B18: PADD 2 | C18: Midwest South | D18: =VLOOKUP(A18,Input!$A$60:$B$110,2,FALSE) -> 2.5 | E18: =VLOOKUP(A18,Input!$A$60:$C$110,3,FALSE) -> 0.7 | F18: =Input!E76 -> 5792 | G18: =(VLOOKUP(C18,Input!$A$5:$I$24,2,FALSE)+VLOOKUP(C18,Input!$A$5:$I$24,3,FALSE))*(D18/VLOOKUP(C18,$N$2:$O$12,2,FALSE)) -> 133768.29 | H18: =G18-I18 -> 96313.171 | I18: =G18*(E18/D18) -> 37455.122 | J18: =VLOOKUP(C18,Input!$A$5:$I$24,4,FALSE)*(D18/VLOOKUP(C18,$N$2:$O$12,2,FALSE)) -> 4019.7561 | K18: =VLOOKUP(C18,Input!$A$5:$I$24,5,FALSE)*(D18/VLOOKUP(C18,$N$2:$O$12,2,FALSE)) -> 19726.585 | L18: =VLOOKUP(C18,Input!$A$5:$I$24,7,FALSE)*(F18/VLOOKUP(C18,$N$2:$P$12,3,FALSE)) -> 39743.596
A19: Kentucky | B19: PADD 2 | C19: Midwest East | D19: =VLOOKUP(A19,Input!$A$60:$B$110,2,FALSE) -> 5.8 | E19: =VLOOKUP(A19,Input!$A$60:$C$110,3,FALSE) -> 1.6 | F19: =Input!E77 -> 8648 | G19: =(VLOOKUP(C19,Input!$A$5:$I$24,2,FALSE)+VLOOKUP(C19,Input!$A$5:$I$24,3,FALSE))*(D19/VLOOKUP(C19,$N$2:$O$12,2,FALSE)) -> 314279.18 | H19: =G19-I19 -> 227581.47 | I19: =G19*(E19/D19) -> 86697.704 | J19: =VLOOKUP(C19,Input!$A$5:$I$24,4,FALSE)*(D19/VLOOKUP(C19,$N$2:$O$12,2,FALSE)) -> 3284.4034 | K19: =VLOOKUP(C19,Input!$A$5:$I$24,5,FALSE)*(D19/VLOOKUP(C19,$N$2:$O$12,2,FALSE)) -> 44486 | L19: =VLOOKUP(C19,Input!$A$5:$I$24,7,FALSE)*(F19/VLOOKUP(C19,$N$2:$P$12,3,FALSE)) -> 67648.055
A20: Louisiana | B20: PADD 3 | C20: Gulf Coast East | D20: =VLOOKUP(A20,Input!$A$60:$B$110,2,FALSE) -> 7.4 | E20: =VLOOKUP(A20,Input!$A$60:$C$110,3,FALSE) -> 5.9 | F20: =Input!E78 -> 17217 | G20: =(VLOOKUP(C20,Input!$A$5:$I$24,2,FALSE)+VLOOKUP(C20,Input!$A$5:$I$24,3,FALSE))*(D20/VLOOKUP(C20,$N$2:$O$12,2,FALSE)) -> 259401.38 | H20: =G20-I20 -> 52581.36 | I20: =G20*(E20/D20) -> 206820.02 | J20: =VLOOKUP(C20,Input!$A$5:$I$24,4,FALSE)*(D20/VLOOKUP(C20,$N$2:$O$12,2,FALSE)) -> 626.04 | K20: =VLOOKUP(C20,Input!$A$5:$I$24,5,FALSE)*(D20/VLOOKUP(C20,$N$2:$O$12,2,FALSE)) -> 46690.744 | L20: =VLOOKUP(C20,Input!$A$5:$I$24,7,FALSE)*(F20/VLOOKUP(C20,$N$2:$P$12,3,FALSE)) -> 232818
A21: Maine | B21: PADD 1 | C21: New England | D21: =VLOOKUP(A21,Input!$A$60:$B$110,2,FALSE) -> 1.7 | E21: =VLOOKUP(A21,Input!$A$60:$C$110,3,FALSE) -> 0 | F21: =Input!E79 -> 1310 | G21: =(VLOOKUP(C21,Input!$A$5:$I$24,2,FALSE)+VLOOKUP(C21,Input!$A$5:$I$24,3,FALSE))*(D21/VLOOKUP(C21,$N$2:$O$12,2,FALSE)) -> 70693.324 | H21: =G21-I21 -> 70693.324 | I21: =G21*(E21/D21) -> 0 | J21: =VLOOKUP(C21,Input!$A$5:$I$24,4,FALSE)*(D21/VLOOKUP(C21,$N$2:$O$12,2,FALSE)) -> 0 | K21: =VLOOKUP(C21,Input!$A$5:$I$24,5,FALSE)*(D21/VLOOKUP(C21,$N$2:$O$12,2,FALSE)) -> 247.2234 | L21: =VLOOKUP(C21,Input!$A$5:$I$24,7,FALSE)*(F21/VLOOKUP(C21,$N$2:$P$12,3,FALSE)) -> 561.91924
A22: Maryland | B22: PADD 1 | C22: Central Atlantic | D22: =VLOOKUP(A22,Input!$A$60:$B$110,2,FALSE) -> 6.8 | E22: =VLOOKUP(A22,Input!$A$60:$C$110,3,FALSE) -> 3.2 | F22: =Input!E80 -> 9391 | G22: =(VLOOKUP(C22,Input!$A$5:$I$24,2,FALSE)+VLOOKUP(C22,Input!$A$5:$I$24,3,FALSE))*(D22/VLOOKUP(C22,$N$2:$O$12,2,FALSE)) -> 259055.47 | H22: =G22-I22 -> 137147.01 | I22: =G22*(E22/D22) -> 121908.46 | J22: =VLOOKUP(C22,Input!$A$5:$I$24,4,FALSE)*(D22/VLOOKUP(C22,$N$2:$O$12,2,FALSE)) -> 78.360771 | K22: =VLOOKUP(C22,Input!$A$5:$I$24,5,FALSE)*(D22/VLOOKUP(C22,$N$2:$O$12,2,FALSE)) -> 20215.412 | L22: =VLOOKUP(C22,Input!$A$5:$I$24,7,FALSE)*(F22/VLOOKUP(C22,$N$2:$P$12,3,FALSE)) -> 54642.494
A23: Massachusetts | B23: PADD 1 | C23: New England | D23: =VLOOKUP(A23,Input!$A$60:$B$110,2,FALSE) -> 6.5 | E23: =VLOOKUP(A23,Input!$A$60:$C$110,3,FALSE) -> 2.2 | F23: =Input!E81 -> 17705 | G23: =(VLOOKUP(C23,Input!$A$5:$I$24,2,FALSE)+VLOOKUP(C23,Input!$A$5:$I$24,3,FALSE))*(D23/VLOOKUP(C23,$N$2:$O$12,2,FALSE)) -> 270298.01 | H23: =G23-I23 -> 178812.53 | I23: =G23*(E23/D23) -> 91485.479 | J23: =VLOOKUP(C23,Input!$A$5:$I$24,4,FALSE)*(D23/VLOOKUP(C23,$N$2:$O$12,2,FALSE)) -> 0 | K23: =VLOOKUP(C23,Input!$A$5:$I$24,5,FALSE)*(D23/VLOOKUP(C23,$N$2:$O$12,2,FALSE)) -> 945.26596 | L23: =VLOOKUP(C23,Input!$A$5:$I$24,7,FALSE)*(F23/VLOOKUP(C23,$N$2:$P$12,3,FALSE)) -> 7594.4887
A24: Michigan | B24: PADD 2 | C24: Midwest East | D24: =VLOOKUP(A24,Input!$A$60:$B$110,2,FALSE) -> 14.3 | E24: =VLOOKUP(A24,Input!$A$60:$C$110,3,FALSE) -> 0.1 | F24: =Input!E82 -> 12660 | G24: =(VLOOKUP(C24,Input!$A$5:$I$24,2,FALSE)+VLOOKUP(C24,Input!$A$5:$I$24,3,FALSE))*(D24/VLOOKUP(C24,$N$2:$O$12,2,FALSE)) -> 774860.73 | H24: =G24-I24 -> 769442.12 | I24: =G24*(E24/D24) -> 5418.6065 | J24: =VLOOKUP(C24,Input!$A$5:$I$24,4,FALSE)*(D24/VLOOKUP(C24,$N$2:$O$12,2,FALSE)) -> 8097.7532 | K24: =VLOOKUP(C24,Input!$A$5:$I$24,5,FALSE)*(D24/VLOOKUP(C24,$N$2:$O$12,2,FALSE)) -> 109681 | L24: =VLOOKUP(C24,Input!$A$5:$I$24,7,FALSE)*(F24/VLOOKUP(C24,$N$2:$P$12,3,FALSE)) -> 99031.497
... A52: Wyoming | B52: PADD 4 | C52: Rocky Mountain | D52: =VLOOKUP(A52,Input!$A$60:$B$110,2,FALSE) -> 2.5 | E52: =VLOOKUP(A52,Input!$A$60:$C$110,3,FALSE) -> 0 | F52: =Input!E110 -> 1227 | G52: =(VLOOKUP(C52,Input!$A$5:$I$24,2,FALSE)+VLOOKUP(C52,Input!$A$5:$I$24,3,FALSE))*(D52/VLOOKUP(C52,$N$2:$O$12,2,FALSE)) -> 60876.636 | H52: =G52-I52 -> 60876.636 | I52: =G52*(E52/D52) -> 0 | J52: =VLOOKUP(C52,Input!$A$5:$I$24,4,FALSE)*(D52/VLOOKUP(C52,$N$2:$O$12,2,FALSE)) -> 378.38785 | K52: =VLOOKUP(C52,Input!$A$5:$I$24,5,FALSE)*(D52/VLOOKUP(C52,$N$2:$O$12,2,FALSE)) -> 24812.033 | L52: =VLOOKUP(C52,Input!$A$5:$I$24,7,FALSE)*(F52/VLOOKUP(C52,$N$2:$P$12,3,FALSE)) -> 401.04634
A53: United States | D53: =SUM(D2:D52) -> 387.5 | E53: =SUM(E2:E52) -> 78.4 | F53: =Input!E111 -> 0 | G53: =SUM(G2:G52) -> 16990587 | H53: =SUM(H2:H52) -> 13482777 | I53: =SUM(I2:I52) -> 3507810.2 | J53: =SUM(J2:J52) -> 168758 | K53: =SUM(K2:K52) -> 2160828 | L53: =SUM(L2:L52) -> 3207768

Sheet Output - State
A1: State | B1: fipstate | C1: HMA Cement [short tons] | D1: WMA Cement [short tons] | E1: Cutback Asphalt [short tons] | F1: Emulsified Asphalt [short tons] | G1: All Roofing [short tons] | I1: Population | J1: HMA kg/person | K1: WMA kg/person | L1: Cutback kg/person | M1: Emulsified kg/person | N1: Roofing kg/person | O1: Heated | P1: Ambient | Q1: Total kg/person | R1: % Heated | S1: % Ambient
A2: Alabama | B2: 1 | C2: =Intermediate!H2*Input!M$4 -> 915.96729 | D2: =Intermediate!I2*Input!N$4 -> 166.42 | E2: =Intermediate!J2*Input!O$4 -> 231.25406 | F2: =Intermediate!K2*Input!P$4 -> 4174.9854 | G2: =Intermediate!L2*Input!Q$4 -> 1826.6572 | I2: 4890000 | J2: =C2*2000*0.453592/$I2 -> 0.1699286 | K2: =D2*2000*0.453592/$I2 -> 0.03087394 | L2: =E2*2000*0.453592/$I2 -> 0.042901837 | M2: =F2*2000*0.453592/$I2 -> 0.77453577 | N2: =G2*2000*0.453592/$I2 -> 0.33887816 | O2: =SUM(J2:K2,N2) -> 0.5396807 | P2: =SUM(L2:M2) -> 0.81743761 | Q2: =SUM(J2:N2) -> 1.3571183 | R2: =O2/Q2 -> 0.39766666 | S2: =P2/Q2 -> 0.60233334
A3: Alaska | B3: 2 | C3: =Intermediate!H3*Input!M$4 -> 375.55703 | D3: =Intermediate!I3*Input!N$4 -> 0 | E3: =Intermediate!J3*Input!O$4 -> 142.18438 | F3: =Intermediate!K3*Input!P$4 -> 1329.2085 | G3: =Intermediate!L3*Input!Q$4 -> 104.5701 | I3: 735000 | J3: =C3*2000*0.453592/$I3 -> 0.4635365 | K3: =D3*2000*0.453592/$I3 -> 0 | L3: =E3*2000*0.453592/$I3 -> 0.17549305 | M3: =F3*2000*0.453592/$I3 -> 1.6405941 | N3: =G3*2000*0.453592/$I3 -> 0.1290671 | O3: =SUM(J3:K3,N3) -> 0.5926036 | P3: =SUM(L3:M3) -> 1.8160872 | Q3: =SUM(J3:N3) -> 2.4086908 | R3: =O3/Q3 -> 0.24602726 | S3: =P3/Q3 -> 0.75397274
A4: Arizona | B4: 4 | C4: =Intermediate!H4*Input!M$4 -> 1370.7831 | D4: =Intermediate!I4*Input!N$4 -> 35.481731 | E4: =Intermediate!J4*Input!O$4 -> 540.30064 | F4: =Intermediate!K4*Input!P$4 -> 5050.9923 | G4: =Intermediate!L4*Input!Q$4 -> 604.71465 | I4: 7160000 | J4: =C4*2000*0.453592/$I4 -> 0.17368052 | K4: =D4*2000*0.453592/$I4 -> 0.0044955948 | L4: =E4*2000*0.453592/$I4 -> 0.068456997 | M4: =F4*2000*0.453592/$I4 -> 0.63996919 | N4: =G4*2000*0.453592/$I4 -> 0.07661836 | O4: =SUM(J4:K4,N4) -> 0.25479448 | P4: =SUM(L4:M4) -> 0.70842619 | Q4: =SUM(J4:N4) -> 0.96322067 | R4: =O4/Q4 -> 0.26452347 | S4: =P4/Q4 -> 0.73547653
A5: Arkansas | B5: 5 | C5: =Intermediate!H5*Input!M$4 -> 880.73778 | D5: =Intermediate!I5*Input!N$4 -> 44.378668 | E5: =Intermediate!J5*Input!O$4 -> 186.38387 | F5: =Intermediate!K5*Input!P$4 -> 3364.9136 | G5: =Intermediate!L5*Input!Q$4 -> 1395.2991 | I5: 3010000 | J5: =C5*2000*0.453592/$I5 -> 0.26544559 | K5: =D5*2000*0.453592/$I5 -> 0.013375288 | L5: =E5*2000*0.453592/$I5 -> 0.05617424 | M5: =F5*2000*0.453592/$I5 -> 1.0141514 | N5: =G5*2000*0.453592/$I5 -> 0.42052924 | O5: =SUM(J5:K5,N5) -> 0.69935012 | P5: =SUM(L5:M5) -> 1.0703257 | Q5: =SUM(J5:N5) -> 1.7696758 | R5: =O5/Q5 -> 0.39518545 | S5: =P5/Q5 -> 0.60481455
A6: California | B6: 6 | C6: =Intermediate!H6*Input!M$4 -> 5224.2697 | D6: =Intermediate!I6*Input!N$4 -> 638.2455 | E6: =Intermediate!J6*Input!O$4 -> 14944.899 | F6: =Intermediate!K6*Input!P$4 -> 10185.415 | G6: =Intermediate!L6*Input!Q$4 -> 3413.6024 | I6: 39500000 | J6: =C6*2000*0.453592/$I6 -> 0.11998415 | K6: =D6*2000*0.453592/$I6 -> 0.014658382 | L6: =E6*2000*0.453592/$I6 -> 0.34323476 | M6: =F6*2000*0.453592/$I6 -> 0.2339252 | N6: =G6*2000*0.453592/$I6 -> 0.078399126 | O6: =SUM(J6:K6,N6) -> 0.21304166 | P6: =SUM(L6:M6) -> 0.57715996 | Q6: =SUM(J6:N6) -> 0.79020162 | R6: =O6/Q6 -> 0.26960418 | S6: =P6/Q6 -> 0.73039582
A7: Colorado | B7: 8 | C7: =Intermediate!H7*Input!M$4 -> 832.06185 | D7: =Intermediate!I7*Input!N$4 -> 77.069821 | E7: =Intermediate!J7*Input!O$4 -> 481.65489 | F7: =Intermediate!K7*Input!P$4 -> 7645.3614 | G7: =Intermediate!L7*Input!Q$4 -> 78.399436 | I7: 5690000 | J7: =C7*2000*0.453592/$I7 -> 0.13265961 | K7: =D7*2000*0.453592/$I7 -> 0.012287611 | L7: =E7*2000*0.453592/$I7 -> 0.07679255 | M7: =F7*2000*0.453592/$I7 -> 1.2189367 | N7: =G7*2000*0.453592/$I7 -> 0.012499598 | O7: =SUM(J7:K7,N7) -> 0.15744682 | P7: =SUM(L7:M7) -> 1.2957292 | Q7: =SUM(J7:N7) -> 1.453176 | R7: =O7/Q7 -> 0.1083467 | S7: =P7/Q7 -> 0.8916533
A8: Connecticut | B8: 9 | C8: =Intermediate!H8*Input!M$4 -> 1023.9096 | D8: =Intermediate!I8*Input!N$4 -> 0 | E8: =Intermediate!J8*Input!O$4 -> 0 | F8: =Intermediate!K8*Input!P$4 -> 70.374905 | G8: =Intermediate!L8*Input!Q$4 -> 38.6543 | I8: 3570000 | J8: =C8*2000*0.453592/$I8 -> 0.26018892 | K8: =D8*2000*0.453592/$I8 -> 0 | L8: =E8*2000*0.453592/$I8 -> 0 | M8: =F8*2000*0.453592/$I8 -> 0.01788319 | N8: =G8*2000*0.453592/$I8 -> 0.0098225664 | O8: =SUM(J8:K8,N8) -> 0.27001149 | P8: =SUM(L8:M8) -> 0.01788319 | Q8: =SUM(J8:N8) -> 0.28789467 | R8: =O8/Q8 -> 0.93788287 | S8: =P8/Q8 -> 0.062117126
A9: Delaware | B9: 10 | C9: =Intermediate!H9*Input!M$4 -> 306.29499 | D9: =Intermediate!I9*Input!N$4 -> 0 | E9: =Intermediate!J9*Input!O$4 -> 7.5223574 | F9: =Intermediate!K9*Input!P$4 -> 469.7586 | G9: =Intermediate!L9*Input!Q$4 -> 237.41579 | I9: 965000 | J9: =C9*2000*0.453592/$I9 -> 0.28794396 | K9: =D9*2000*0.453592/$I9 -> 0 | L9: =E9*2000*0.453592/$I9 -> 0.0070716708 | M9: =F9*2000*0.453592/$I9 -> 0.44161397 | N9: =G9*2000*0.453592/$I9 -> 0.22319151 | O9: =SUM(J9:K9,N9) -> 0.51113546 | P9: =SUM(L9:M9) -> 0.44868564 | Q9: =SUM(J9:N9) -> 0.95982111 | R9: =O9/Q9 -> 0.53253201 | S9: =P9/Q9 -> 0.46746799
A10: District of Columbia | B10: 11 | C10: =Intermediate!H10*Input!M$4 -> 287.15156 | D10: =Intermediate!I10*Input!N$4 -> 0 | E10: =Intermediate!J10*Input!O$4 -> 7.0522101 | F10: =Intermediate!K10*Input!P$4 -> 440.39869 | G10: =Intermediate!L10*Input!Q$4 -> 462.50642 | I10: 702000 | J10: =C10*2000*0.453592/$I10 -> 0.37108162 | K10: =D10*2000*0.453592/$I10 -> 0 | L10: =E10*2000*0.453592/$I10 -> 0.0091134646 | M10: =F10*2000*0.453592/$I10 -> 0.56912057 | N10: =G10*2000*0.453592/$I10 -> 0.59769007 | O10: =SUM(J10:K10,N10) -> 0.96877169 | P10: =SUM(L10:M10) -> 0.57823404 | Q10: =SUM(J10:N10) -> 1.5470057 | R10: =O10/Q10 -> 0.62622373 | S10: =P10/Q10 -> 0.37377627
A11: Florida | B11: 12 | C11: =Intermediate!H11*Input!M$4 -> 2776.8444 | D11: =Intermediate!I11*Input!N$4 -> 264.23704 | E11: =Intermediate!J11*Input!O$4 -> 99.815056 | F11: =Intermediate!K11*Input!P$4 -> 4656.6133 | G11: =Intermediate!L11*Input!Q$4 -> 2666.0018 | I11: 21200000 | J11: =C11*2000*0.453592/$I11 -> 0.11882589 | K11: =D11*2000*0.453592/$I11 -> 0.011307152 | L11: =E11*2000*0.453592/$I11 -> 0.0042712557 | M11: =F11*2000*0.453592/$I11 -> 0.19926439 | N11: =G11*2000*0.453592/$I11 -> 0.11408274 | O11: =SUM(J11:K11,N11) -> 0.24421578 | P11: =SUM(L11:M11) -> 0.20353565 | Q11: =SUM(J11:N11) -> 0.44775143 | R11: =O11/Q11 -> 0.54542714 | S11: =P11/Q11 -> 0.45457286
A12: Georgia | B12: 13 | C12: =Intermediate!H12*Input!M$4 -> 2836.7763 | D12: =Intermediate!I12*Input!N$4 -> 0 | E12: =Intermediate!J12*Input!O$4 -> 88.585862 | F12: =Intermediate!K12*Input!P$4 -> 4132.7443 | G12: =Intermediate!L12*Input!Q$4 -> 1373.637 | I12: 10500000 | J12: =C12*2000*0.453592/$I12 -> 0.24509315 | K12: =D12*2000*0.453592/$I12 -> 0 | L12: =E12*2000*0.453592/$I12 -> 0.0076536835 | M12: =F12*2000*0.453592/$I12 -> 0.35706281 | N12: =G12*2000*0.453592/$I12 -> 0.11868015 | O12: =SUM(J12:K12,N12) -> 0.3637733 | P12: =SUM(L12:M12) -> 0.3647165 | Q12: =SUM(J12:N12) -> 0.7284898 | R12: =O12/Q12 -> 0.49935264 | S12: =P12/Q12 -> 0.50064736
A13: Hawaii | B13: 15 | C13: =Intermediate!H13*Input!M$4 -> 206.55636 | D13: =Intermediate!I13*Input!N$4 -> 0 | E13: =Intermediate!J13*Input!O$4 -> 78.201408 | F13: =Intermediate!K13*Input!P$4 -> 731.06468 | G13: =Intermediate!L13*Input!Q$4 -> 271.61224 | I13: 1420000 | J13: =C13*2000*0.453592/$I13 -> 0.13196101 | K13: =D13*2000*0.453592/$I13 -> 0 | L13: =E13*2000*0.453592/$I13 -> 0.049959906 | M13: =F13*2000*0.453592/$I13 -> 0.46704942 | N13: =G13*2000*0.453592/$I13 -> 0.17352273 | O13: =SUM(J13:K13,N13) -> 0.30548374 | P13: =SUM(L13:M13) -> 0.51700933 | Q13: =SUM(J13:N13) -> 0.82249307 | R13: =O13/Q13 -> 0.37141193 | S13: =P13/Q13 -> 0.62858807
... A52: Wyoming | B52: 56 | C52: =Intermediate!H52*Input!M$4 -> 305.90509 | D52: =Intermediate!I52*Input!N$4 -> 0 | E52: =Intermediate!J52*Input!O$4 -> 154.37657 | F52: =Intermediate!K52*Input!P$4 -> 2450.4364 | G52: =Intermediate!L52*Input!Q$4 -> 7.1992298 | I52: 578000 | J52: =C52*2000*0.453592/$I52 -> 0.48012492 | K52: =D52*2000*0.453592/$I52 -> 0 | L52: =E52*2000*0.453592/$I52 -> 0.24229749 | M52: =F52*2000*0.453592/$I52 -> 3.846015 | N52: =G52*2000*0.453592/$I52 -> 0.011299353 | O52: =SUM(J52:K52,N52) -> 0.49142428 | P52: =SUM(L52:M52) -> 4.0883125 | Q52: =SUM(J52:N52) -> 4.5797367 | R52: =O52/Q52 -> 0.10730405 | S52: =P52/Q52 -> 0.89269595
A53: United States | C53: =SUM(C2:C52) -> 67750.953 | D53: =SUM(D2:D52) -> 11102.219 | E53: =SUM(E2:E52) -> 68850.733 | F53: =SUM(F2:F52) -> 213403.37 | G53: =SUM(G2:G52) -> 57583.019

Sheet Output - County
A1: fipstate | B1: fipscty | C1: HMA Cement [short tons] | D1: WMA Cement [short tons] | E1: Cutback Asphalt [short tons] | F1: Emulsified Asphalt [short tons] | G1: All Roofing [short tons]
A2: 1 | B2: 1 | C2: =SUMIFS(Input!$C$115:$C$3257,Input!$A$115:$A$3257,"="&'Output - County'!A2,Input!$B$115:$B$3257,"="&'Output - County'!B2)*VLOOKUP(A2,'Output - State'!$B$2:$G$52,2,FALSE) -> 10.736022 | D2: =SUMIFS(Input!$C$115:$C$3257,Input!$A$115:$A$3257,"="&'Output - County'!A2,Input!$B$115:$B$3257,"="&'Output - County'!B2)*VLOOKUP(A2,'Output - State'!$B$2:$G$52,3,FALSE) -> 1.9506033 | E2: =SUMIFS(Input!$C$115:$C$3257,Input!$A$115:$A$3257,"="&'Output - County'!A2,Input!$B$115:$B$3257,"="&'Output - County'!B2)*VLOOKUP(A2,'Output - State'!$B$2:$G$52,4,FALSE) -> 2.7105211 | F2: =SUMIFS(Input!$C$115:$C$3257,Input!$A$115:$A$3257,"="&'Output - County'!A2,Input!$B$115:$B$3257,"="&'Output - County'!B2)*VLOOKUP(A2,'Output - State'!$B$2:$G$52,5,FALSE) -> 48.934864 | G2: =SUMIFS(Input!$D$115:$D$3257,Input!$A$115:$A$3257,"="&'Output - County'!A2,Input!$B$115:$B$3257,"="&'Output - County'!B2)*VLOOKUP(A2,'Output - State'!$B$2:$G$52,6,FALSE) -> 20.738573
A3: 1 | B3: 3 | C3: =SUMIFS(Input!$C$115:$C$3257,Input!$A$115:$A$3257,"="&'Output - County'!A3,Input!$B$115:$B$3257,"="&'Output - County'!B3)*VLOOKUP(A3,'Output - State'!$B$2:$G$52,2,FALSE) -> 50.039842 | D3: =SUMIFS(Input!$C$115:$C$3257,Input!$A$115:$A$3257,"="&'Output - County'!A3,Input!$B$115:$B$3257,"="&'Output - County'!B3)*VLOOKUP(A3,'Output - State'!$B$2:$G$52,3,FALSE) -> 9.0916246 | E3: =SUMIFS(Input!$C$115:$C$3257,Input!$A$115:$A$3257,"="&'Output - County'!A3,Input!$B$115:$B$3257,"="&'Output - County'!B3)*VLOOKUP(A3,'Output - State'!$B$2:$G$52,4,FALSE) -> 12.633548 | F3: =SUMIFS(Input!$C$115:$C$3257,Input!$A$115:$A$3257,"="&'Output - County'!A3,Input!$B$115:$B$3257,"="&'Output - County'!B3)*VLOOKUP(A3,'Output - State'!$B$2:$G$52,5,FALSE) -> 228.08195 | G3: =SUMIFS(Input!$D$115:$D$3257,Input!$A$115:$A$3257,"="&'Output - County'!A3,Input!$B$115:$B$3257,"="&'Output - County'!B3)*VLOOKUP(A3,'Output - State'!$B$2:$G$52,6,FALSE) -> 81.459619
A4: 1 | B4: 5 | C4: =SUMIFS(Input!$C$115:$C$3257,Input!$A$115:$A$3257,"="&'Output - County'!A4,Input!$B$115:$B$3257,"="&'Output - County'!B4)*VLOOKUP(A4,'Output - State'!$B$2:$G$52,2,FALSE) -> 4.5084429 | D4: =SUMIFS(Input!$C$115:$C$3257,Input!$A$115:$A$3257,"="&'Output - County'!A4,Input!$B$115:$B$3257,"="&'Output - County'!B4)*VLOOKUP(A4,'Output - State'!$B$2:$G$52,3,FALSE) -> 0.8191287 | E4: =SUMIFS(Input!$C$115:$C$3257,Input!$A$115:$A$3257,"="&'Output - County'!A4,Input!$B$115:$B$3257,"="&'Output - County'!B4)*VLOOKUP(A4,'Output - State'!$B$2:$G$52,4,FALSE) -> 1.1382456 | F4: =SUMIFS(Input!$C$115:$C$3257,Input!$A$115:$A$3257,"="&'Output - County'!A4,Input!$B$115:$B$3257,"="&'Output - County'!B4)*VLOOKUP(A4,'Output - State'!$B$2:$G$52,5,FALSE) -> 20.549515 | G4: =SUMIFS(Input!$D$115:$D$3257,Input!$A$115:$A$3257,"="&'Output - County'!A4,Input!$B$115:$B$3257,"="&'Output - County'!B4)*VLOOKUP(A4,'Output - State'!$B$2:$G$52,6,FALSE) -> 9.3043326
A5: 1 | B5: 7 | C5: =SUMIFS(Input!$C$115:$C$3257,Input!$A$115:$A$3257,"="&'Output - County'!A5,Input!$B$115:$B$3257,"="&'Output - County'!B5)*VLOOKUP(A5,'Output - State'!$B$2:$G$52,2,FALSE) -> 3.4787264 | D5: =SUMIFS(Input!$C$115:$C$3257,Input!$A$115:$A$3257,"="&'Output - County'!A5,Input!$B$115:$B$3257,"="&'Output - County'!B5)*VLOOKUP(A5,'Output - State'!$B$2:$G$52,3,FALSE) -> 0.63204185 | E5: =SUMIFS(Input!$C$115:$C$3257,Input!$A$115:$A$3257,"="&'Output - County'!A5,Input!$B$115:$B$3257,"="&'Output - County'!B5)*VLOOKUP(A5,'Output - State'!$B$2:$G$52,4,FALSE) -> 0.87827327 | F5: =SUMIFS(Input!$C$115:$C$3257,Input!$A$115:$A$3257,"="&'Output - County'!A5,Input!$B$115:$B$3257,"="&'Output - County'!B5)*VLOOKUP(A5,'Output - State'!$B$2:$G$52,5,FALSE) -> 15.856059 | G5: =SUMIFS(Input!$D$115:$D$3257,Input!$A$115:$A$3257,"="&'Output - County'!A5,Input!$B$115:$B$3257,"="&'Output - County'!B5)*VLOOKUP(A5,'Output - State'!$B$2:$G$52,6,FALSE) -> 8.3701627
A6: 1 | B6: 9 | C6: =SUMIFS(Input!$C$115:$C$3257,Input!$A$115:$A$3257,"="&'Output - County'!A6,Input!$B$115:$B$3257,"="&'Output - County'!B6)*VLOOKUP(A6,'Output - State'!$B$2:$G$52,2,FALSE) -> 8.7816273 | D6: =SUMIFS(Input!$C$115:$C$3257,Input!$A$115:$A$3257,"="&'Output - County'!A6,Input!$B$115:$B$3257,"="&'Output - County'!B6)*VLOOKUP(A6,'Output - State'!$B$2:$G$52,3,FALSE) -> 1.5955138 | E6: =SUMIFS(Input!$C$115:$C$3257,Input!$A$115:$A$3257,"="&'Output - County'!A6,Input!$B$115:$B$3257,"="&'Output - County'!B6)*VLOOKUP(A6,'Output - State'!$B$2:$G$52,4,FALSE) -> 2.2170955 | F6: =SUMIFS(Input!$C$115:$C$3257,Input!$A$115:$A$3257,"="&'Output - County'!A6,Input!$B$115:$B$3257,"="&'Output - County'!B6)*VLOOKUP(A6,'Output - State'!$B$2:$G$52,5,FALSE) -> 40.026719 | G6: =SUMIFS(Input!$D$115:$D$3257,Input!$A$115:$A$3257,"="&'Output - County'!A6,Input!$B$115:$B$3257,"="&'Output - County'!B6)*VLOOKUP(A6,'Output - State'!$B$2:$G$52,6,FALSE) -> 21.598009
A7: 1 | B7: 11 | C7: =SUMIFS(Input!$C$115:$C$3257,Input!$A$115:$A$3257,"="&'Output - County'!A7,Input!$B$115:$B$3257,"="&'Output - County'!B7)*VLOOKUP(A7,'Output - State'!$B$2:$G$52,2,FALSE) -> 1.7003274 | D7: =SUMIFS(Input!$C$115:$C$3257,Input!$A$115:$A$3257,"="&'Output - County'!A7,Input!$B$115:$B$3257,"="&'Output - County'!B7)*VLOOKUP(A7,'Output - State'!$B$2:$G$52,3,FALSE) -> 0.3089286 | E7: =SUMIFS(Input!$C$115:$C$3257,Input!$A$115:$A$3257,"="&'Output - County'!A7,Input!$B$115:$B$3257,"="&'Output - County'!B7)*VLOOKUP(A7,'Output - State'!$B$2:$G$52,4,FALSE) -> 0.42928129 | F7: =SUMIFS(Input!$C$115:$C$3257,Input!$A$115:$A$3257,"="&'Output - County'!A7,Input!$B$115:$B$3257,"="&'Output - County'!B7)*VLOOKUP(A7,'Output - State'!$B$2:$G$52,5,FALSE) -> 7.7501044 | G7: =SUMIFS(Input!$D$115:$D$3257,Input!$A$115:$A$3257,"="&'Output - County'!A7,Input!$B$115:$B$3257,"="&'Output - County'!B7)*VLOOKUP(A7,'Output - State'!$B$2:$G$52,6,FALSE) -> 3.8114134
A8: 1 | B8: 13 | C8: =SUMIFS(Input!$C$115:$C$3257,Input!$A$115:$A$3257,"="&'Output - County'!A8,Input!$B$115:$B$3257,"="&'Output - County'!B8)*VLOOKUP(A8,'Output - State'!$B$2:$G$52,2,FALSE) -> 8.3939203 | D8: =SUMIFS(Input!$C$115:$C$3257,Input!$A$115:$A$3257,"="&'Output - County'!A8,Input!$B$115:$B$3257,"="&'Output - County'!B8)*VLOOKUP(A8,'Output - State'!$B$2:$G$52,3,FALSE) -> 1.5250722 | E8: =SUMIFS(Input!$C$115:$C$3257,Input!$A$115:$A$3257,"="&'Output - County'!A8,Input!$B$115:$B$3257,"="&'Output - County'!B8)*VLOOKUP(A8,'Output - State'!$B$2:$G$52,4,FALSE) -> 2.1192112 | F8: =SUMIFS(Input!$C$115:$C$3257,Input!$A$115:$A$3257,"="&'Output - County'!A8,Input!$B$115:$B$3257,"="&'Output - County'!B8)*VLOOKUP(A8,'Output - State'!$B$2:$G$52,5,FALSE) -> 38.259548 | G8: =SUMIFS(Input!$D$115:$D$3257,Input!$A$115:$A$3257,"="&'Output - County'!A8,Input!$B$115:$B$3257,"="&'Output - County'!B8)*VLOOKUP(A8,'Output - State'!$B$2:$G$52,6,FALSE) -> 7.3238923
A9: 1 | B9: 15 | C9: =SUMIFS(Input!$C$115:$C$3257,Input!$A$115:$A$3257,"="&'Output - County'!A9,Input!$B$115:$B$3257,"="&'Output - County'!B9)*VLOOKUP(A9,'Output - State'!$B$2:$G$52,2,FALSE) -> 19.652018 | D9: =SUMIFS(Input!$C$115:$C$3257,Input!$A$115:$A$3257,"="&'Output - County'!A9,Input!$B$115:$B$3257,"="&'Output - County'!B9)*VLOOKUP(A9,'Output - State'!$B$2:$G$52,3,FALSE) -> 3.5705303 | E9: =SUMIFS(Input!$C$115:$C$3257,Input!$A$115:$A$3257,"="&'Output - County'!A9,Input!$B$115:$B$3257,"="&'Output - County'!B9)*VLOOKUP(A9,'Output - State'!$B$2:$G$52,4,FALSE) -> 4.9615407 | F9: =SUMIFS(Input!$C$115:$C$3257,Input!$A$115:$A$3257,"="&'Output - County'!A9,Input!$B$115:$B$3257,"="&'Output - County'!B9)*VLOOKUP(A9,'Output - State'!$B$2:$G$52,5,FALSE) -> 89.574038 | G9: =SUMIFS(Input!$D$115:$D$3257,Input!$A$115:$A$3257,"="&'Output - County'!A9,Input!$B$115:$B$3257,"="&'Output - County'!B9)*VLOOKUP(A9,'Output - State'!$B$2:$G$52,6,FALSE) -> 42.598149
A10: 1 | B10: 17 | C10: =SUMIFS(Input!$C$115:$C$3257,Input!$A$115:$A$3257,"="&'Output - County'!A10,Input!$B$115:$B$3257,"="&'Output - County'!B10)*VLOOKUP(A10,'Output - State'!$B$2:$G$52,2,FALSE) -> 6.3800077 | D10: =SUMIFS(Input!$C$115:$C$3257,Input!$A$115:$A$3257,"="&'Output - County'!A10,Input!$B$115:$B$3257,"="&'Output - County'!B10)*VLOOKUP(A10,'Output - State'!$B$2:$G$52,3,FALSE) -> 1.159169 | E10: =SUMIFS(Input!$C$115:$C$3257,Input!$A$115:$A$3257,"="&'Output - County'!A10,Input!$B$115:$B$3257,"="&'Output - County'!B10)*VLOOKUP(A10,'Output - State'!$B$2:$G$52,4,FALSE) -> 1.6107591 | F10: =SUMIFS(Input!$C$115:$C$3257,Input!$A$115:$A$3257,"="&'Output - County'!A10,Input!$B$115:$B$3257,"="&'Output - County'!B10)*VLOOKUP(A10,'Output - State'!$B$2:$G$52,5,FALSE) -> 29.08012 | G10: =SUMIFS(Input!$D$115:$D$3257,Input!$A$115:$A$3257,"="&'Output - County'!A10,Input!$B$115:$B$3257,"="&'Output - County'!B10)*VLOOKUP(A10,'Output - State'!$B$2:$G$52,6,FALSE) -> 12.555244
A11: 1 | B11: 19 | C11: =SUMIFS(Input!$C$115:$C$3257,Input!$A$115:$A$3257,"="&'Output - County'!A11,Input!$B$115:$B$3257,"="&'Output - County'!B11)*VLOOKUP(A11,'Output - State'!$B$2:$G$52,2,FALSE) -> 3.716371 | D11: =SUMIFS(Input!$C$115:$C$3257,Input!$A$115:$A$3257,"="&'Output - County'!A11,Input!$B$115:$B$3257,"="&'Output - County'!B11)*VLOOKUP(A11,'Output - State'!$B$2:$G$52,3,FALSE) -> 0.67521896 | E11: =SUMIFS(Input!$C$115:$C$3257,Input!$A$115:$A$3257,"="&'Output - County'!A11,Input!$B$115:$B$3257,"="&'Output - County'!B11)*VLOOKUP(A11,'Output - State'!$B$2:$G$52,4,FALSE) -> 0.93827137 | F11: =SUMIFS(Input!$C$115:$C$3257,Input!$A$115:$A$3257,"="&'Output - County'!A11,Input!$B$115:$B$3257,"="&'Output - County'!B11)*VLOOKUP(A11,'Output - State'!$B$2:$G$52,5,FALSE) -> 16.939245 | G11: =SUMIFS(Input!$D$115:$D$3257,Input!$A$115:$A$3257,"="&'Output - County'!A11,Input!$B$115:$B$3257,"="&'Output - County'!B11)*VLOOKUP(A11,'Output - State'!$B$2:$G$52,6,FALSE) -> 9.7153674
A12: 1 | B12: 21 | C12: =SUMIFS(Input!$C$115:$C$3257,Input!$A$115:$A$3257,"="&'Output - County'!A12,Input!$B$115:$B$3257,"="&'Output - County'!B12)*VLOOKUP(A12,'Output - State'!$B$2:$G$52,2,FALSE) -> 11.517394 | D12: =SUMIFS(Input!$C$115:$C$3257,Input!$A$115:$A$3257,"="&'Output - County'!A12,Input!$B$115:$B$3257,"="&'Output - County'!B12)*VLOOKUP(A12,'Output - State'!$B$2:$G$52,3,FALSE) -> 2.092569 | E12: =SUMIFS(Input!$C$115:$C$3257,Input!$A$115:$A$3257,"="&'Output - County'!A12,Input!$B$115:$B$3257,"="&'Output - County'!B12)*VLOOKUP(A12,'Output - State'!$B$2:$G$52,4,FALSE) -> 2.9077939 | F12: =SUMIFS(Input!$C$115:$C$3257,Input!$A$115:$A$3257,"="&'Output - County'!A12,Input!$B$115:$B$3257,"="&'Output - County'!B12)*VLOOKUP(A12,'Output - State'!$B$2:$G$52,5,FALSE) -> 52.496363 | G12: =SUMIFS(Input!$D$115:$D$3257,Input!$A$115:$A$3257,"="&'Output - County'!A12,Input!$B$115:$B$3257,"="&'Output - County'!B12)*VLOOKUP(A12,'Output - State'!$B$2:$G$52,6,FALSE) -> 16.516125
A13: 1 | B13: 23 | C13: =SUMIFS(Input!$C$115:$C$3257,Input!$A$115:$A$3257,"="&'Output - County'!A13,Input!$B$115:$B$3257,"="&'Output - County'!B13)*VLOOKUP(A13,'Output - State'!$B$2:$G$52,2,FALSE) -> 2.0969381 | D13: =SUMIFS(Input!$C$115:$C$3257,Input!$A$115:$A$3257,"="&'Output - County'!A13,Input!$B$115:$B$3257,"="&'Output - County'!B13)*VLOOKUP(A13,'Output - State'!$B$2:$G$52,3,FALSE) -> 0.38098789 | E13: =SUMIFS(Input!$C$115:$C$3257,Input!$A$115:$A$3257,"="&'Output - County'!A13,Input!$B$115:$B$3257,"="&'Output - County'!B13)*VLOOKUP(A13,'Output - State'!$B$2:$G$52,4,FALSE) -> 0.52941349 | F13: =SUMIFS(Input!$C$115:$C$3257,Input!$A$115:$A$3257,"="&'Output - County'!A13,Input!$B$115:$B$3257,"="&'Output - County'!B13)*VLOOKUP(A13,'Output - State'!$B$2:$G$52,5,FALSE) -> 9.5578586 | G13: =SUMIFS(Input!$D$115:$D$3257,Input!$A$115:$A$3257,"="&'Output - County'!A13,Input!$B$115:$B$3257,"="&'Output - County'!B13)*VLOOKUP(A13,'Output - State'!$B$2:$G$52,6,FALSE) -> 4.7829501
... A3144: 56 | B3144: 45 | C3144: =SUMIFS(Input!$C$115:$C$3257,Input!$A$115:$A$3257,"="&'Output - County'!A3144,Input!$B$115:$B$3257,"="&'Output - County'!B3144)*VLOOKUP(A3144,'Output - State'!$B$2:$G$52,2,FALSE) -> 1.8207629 | D3144: =SUMIFS(Input!$C$115:$C$3257,Input!$A$115:$A$3257,"="&'Output - County'!A3144,Input!$B$115:$B$3257,"="&'Output - County'!B3144)*VLOOKUP(A3144,'Output - State'!$B$2:$G$52,3,FALSE) -> 0 | E3144: =SUMIFS(Input!$C$115:$C$3257,Input!$A$115:$A$3257,"="&'Output - County'!A3144,Input!$B$115:$B$3257,"="&'Output - County'!B3144)*VLOOKUP(A3144,'Output - State'!$B$2:$G$52,4,FALSE) -> 0.91885727 | F3144: =SUMIFS(Input!$C$115:$C$3257,Input!$A$115:$A$3257,"="&'Output - County'!A3144,Input!$B$115:$B$3257,"="&'Output - County'!B3144)*VLOOKUP(A3144,'Output - State'!$B$2:$G$52,5,FALSE) -> 14.585123 | G3144: =SUMIFS(Input!$D$115:$D$3257,Input!$A$115:$A$3257,"="&'Output - County'!A3144,Input!$B$115:$B$3257,"="&'Output - County'!B3144)*VLOOKUP(A3144,'Output - State'!$B$2:$G$52,6,FALSE) -> 0.086222797
A3145: Total | B3145: Total | C3145: =SUM(C2:C3144) -> 67748.713 | D3145: =SUM(D2:D3144) -> 11102.219 | E3145: =SUM(E2:E3144) -> 68848.07 | F3145: =SUM(F2:F3144) -> 213396.29 | G3145: =SUM(G2:G3144) -> 57577.946
